<?xml version="1.0" ?>
<!-- =================================================================================== -->
<!-- |    This document was autogenerated by xacro from widowx_arm.urdf.xacro          | -->
<!-- |    EDITING THIS FILE BY HAND IS NOT RECOMMENDED                                 | -->
<!-- =================================================================================== -->
<robot name="widowx_arm" xmlns:xacro="http://ros.org/wiki/xacro">
  
  <link name="base_footprint">
  </link>
  <!-- links -->
  <link name="arm_base_link">
    <visual>
      <origin rpy="0 0 0" xyz="0 0 0"/>
      <geometry>
        <mesh filename="package://widowx_arm_description/meshes/base_link.stl"/>
      </geometry>
    </visual>
    <collision>
      <origin rpy="0 0 0" xyz="0 0 0"/>
      <geometry>
        <mesh filename="package://widowx_arm_description/meshes/base_link.stl"/>
      </geometry>
    </collision>
  </link>
  <link name="shoulder_link">
    <visual>
      <origin rpy="0 0 0" xyz="0 0 0"/>
      <geometry>
        <mesh filename="package://widowx_arm_description/meshes/shoulder_link.stl"/>
      </geometry>
    </visual>
    <collision>
      <origin rpy="0 0 0" xyz="0 0 0"/>
      <geometry>
        <mesh filename="package://widowx_arm_description/meshes/shoulder_link.stl"/>
      </geometry>
    </collision>
  </link>
  <link name="biceps_link">
    <visual>
      <origin xyz="0 0 0" rpy="0 0 0" />
      <geometry>
        <mesh filename="package://widowx_arm_description/meshes/biceps_link.new.stl"/>
      </geometry>
    </visual>
    <collision>
      <origin rpy="0 0 0" xyz="0 0 0"/>
      <geometry>
        <mesh filename="package://widowx_arm_description/meshes/biceps_link.new.stl"/>
      </geometry>
    </collision>
  </link>
  <link name="forearm_link">
    <visual>
      <origin xyz="0 0 0" rpy="0 0 0" />
      <geometry>
        <mesh filename="package://widowx_arm_description/meshes/forearm_link.new.stl"/>
      </geometry>
    </visual>
    <collision>
      <origin rpy="0 0 0" xyz="0 0 0"/>
      <geometry>
        <mesh filename="package://widowx_arm_description/meshes/forearm_link.new.stl"/>
      </geometry>
    </collision>
  </link>
  <link name="wrist_1_link">
    <visual>
      <origin rpy="0 0 0" xyz="0 0 0"/>
      <geometry>
        <mesh filename="package://widowx_arm_description/meshes/wrist_1_link.stl"/>
      </geometry>
    </visual>
    <collision>
      <origin rpy="0 0 0" xyz="0 0 0"/>
      <geometry>
        <mesh filename="package://widowx_arm_description/meshes/wrist_1_link.stl"/>
      </geometry>
    </collision>
  </link>
  <link name="wrist_2_link">
    <visual>
      <origin rpy="0 0 0" xyz="0 0 0"/>
      <geometry>
        <mesh filename="package://widowx_arm_description/meshes/wrist_2_link.new.stl"/>
      </geometry>
    </visual>
    <collision>
      <origin rpy="0 0 0" xyz="0 0 0"/>
      <geometry>
        <mesh filename="package://widowx_arm_description/meshes/wrist_2_link.new.stl"/>
      </geometry>
    </collision>
  </link>
 
  <!-- joints -->
  <joint name="arm_base_joint" type="fixed">
    <origin rpy="0.0 0.0 0.0" xyz="0.0 0.0 0.0"/>
    <parent link="base_footprint"/>
    <child link="arm_base_link"/>
  </joint>
  <joint name="joint_1" type="revolute"> <!--shoulder pan-->
    <origin rpy="0 0 0" xyz="0 0 0.125"/>
    <parent link="arm_base_link"/>
    <child link="shoulder_link"/>
    <axis xyz="0 0 1"/>
    <limit effort="0" lower="-2.617" upper="2.617" velocity="0.785"/>
  </joint>
  <joint name="joint_2" type="revolute"> <!--bicep / shoulder tilt-->
    <origin rpy="0 0 0" xyz="0 0 0"/>
    <parent link="shoulder_link"/>
    <child link="biceps_link"/>
    <axis xyz="0 1 0"/>
    <limit effort="0" lower="-1.571" upper="1.571" velocity="1.571"/>
  </joint>
  <joint name="joint_3" type="revolute"> <!-- forearm / tilt -->
    <origin rpy="0 1.570795 0" xyz="0.04825 0 0.14203"/>
    <parent link="biceps_link"/>
    <child link="forearm_link"/>
    <axis xyz="0 1 0"/>
    <limit effort="0" lower="-1.571" upper="1.571" velocity="1.571"/>
  </joint>
  <joint name="joint_4" type="revolute"> <!-- wrist flex -->
    <origin rpy="0 0 0" xyz="0 0 0.14203"/>
    <parent link="forearm_link"/>
    <child link="wrist_1_link"/>
    <axis xyz="0 1 0"/>
    <limit effort="0" lower="-1.745" upper="1.745" velocity="1.571"/>
  </joint>
  <joint name="joint_5" type="revolute"> <!-- wrist rotate -->
    <origin rpy="0 0 0" xyz="0 0 0.0715"/>
    <parent link="wrist_1_link"/>
    <child link="wrist_2_link"/>
    <!--axis xyz="0 0 1"/-->
    <axis xyz="1 0 0"/> <!-- needed for ikfast solution -->
    <limit effort="0" lower="-2.617" upper="2.617" velocity="1.571"/>
  </joint>

</robot>
